  <?xml version="1.0" ?><!-- =================================================================================== --><!-- |    This document was autogenerated by xacro from ../../baxter/urdf/urdf.xacro   | --><!-- |    EDITING THIS FILE BY HAND IS NOT RECOMMENDED                                 | --><!-- =================================================================================== --><robot name="baxter" xmlns:controller="http://playerstage.sourceforge.net/gazebo/xmlschema/#controller" xmlns:interface="http://playerstage.sourceforge.net/gazebo/xmlschema/#interface" xmlns:sensor="http://playerstage.sourceforge.net/gazebo/xmlschema/#sensor" xmlns:xacro="http://playerstage.sourceforge.net/gazebo/xmlschema/#interface">
    <link name="base">
      <inertial>
        <origin rpy="0 0 0" xyz="0 0 0"/>
        <mass value="0.0001"/>
        <inertia ixx="1e-08" ixy="0" ixz="0" iyy="1e-08" iyz="0" izz="1e-08"/>
      </inertial>
    </link>
    <link name="torso">
      <visual>
        <origin rpy="0 0 0" xyz="0 0 0"/>
        <geometry>
          <!-- <box size="0.2 0.35 0.4" /> -->
          <mesh filename="package://baxter_description/meshes/torso/base_link.DAE"/>
        </geometry>
        <material name="darkgray">
          <color rgba=".2 .2 .2 1"/>
        </material>
      </visual>
      <collision>
        <origin rpy="0 0 0" xyz="-0.065 0 0.0"/>
        <geometry>
          <cylinder length="0.7" radius="0.27"/>
        </geometry>
      </collision>
      <inertial>
        <origin rpy="0 0 0" xyz="0.000000 0.000000 0.000000"/>
        <mass value="35.336455"/>
        <inertia ixx="1.849155" ixy="-0.000354" ixz="-0.154188" iyy="1.662671" iyz="0.003292" izz="0.802239"/>
      </inertial>
    </link>
    <link name="left_torso_itb">
      <!-- note: invisible -->
      <!--
           <visual>
             <origin xyz="0 0 0" rpy="0 0 0" />
             <geometry>
               <box size=".059 0.118  0.032" />
             </geometry>
             <material name="white">
               <color rgba="1 1 1 1" />
             </material>
           </visual>
           -->
      <inertial>
        <origin rpy="0 0 0" xyz="0.000000 0.000000 0.000000"/>
        <mass value="0.0001"/>
        <inertia ixx="1e-08" ixy="0" ixz="0" iyy="1e-08" iyz="0" izz="1e-08"/>
      </inertial>
    </link>
    <link name="right_torso_itb">
      <!-- note: invisible -->
      <!--
           <visual>
             <origin xyz="0 0 0" rpy="0 0 0" />
             <geometry>
               <box size=".059 0.118  0.032" />
             </geometry>
             <material name="white">
               <color rgba="1 1 1 1" />
             </material>
           </visual>
           -->
      <inertial>
        <origin rpy="0 0 0" xyz="0.000000 0.000000 0.000000"/>
        <mass value="0.0001"/>
        <inertia ixx="1e-08" ixy="0" ixz="0" iyy="1e-08" iyz="0" izz="1e-08"/>
      </inertial>
    </link>
    <link name="head">
      <visual>
        <origin rpy="0 0 0" xyz="0 0 .00953"/>
        <geometry>
          <!-- <cylinder length="0.04" radius="0.09"/> -->
          <mesh filename="package://baxter_description/meshes/head/H0.DAE"/>
        </geometry>
        <material name="darkgray">
          <color rgba=".2 .2 .2 1"/>
        </material>
      </visual>
      <collision>
        <origin rpy="0 0 0" xyz="0.0 0 0.0"/>
        <geometry>
          <sphere radius="0.001"/>
        </geometry>
      </collision>
      <inertial>
        <origin rpy="0 0 0" xyz="0 0 0"/>
        <mass value="0.547767"/>
        <inertia ixx="0.004641" ixy="0.000159" ixz="0.000242" iyy="0.003295" iyz="-0.001324" izz="0.003415"/>
      </inertial>
    </link>
    <link name="sonar_ring">
      <visual>
        <origin rpy="0 0 0" xyz="-.0347 0 .00953"/>
        <geometry>
          <cylinder length="0.01" radius="0.085"/>
        </geometry>
        <material name="darkgray">
          <color rgba=".2 .2 .2 1"/>
        </material>
      </visual>
      <collision>
        <origin rpy="0 0 0" xyz="0.0 0 0.0"/>
        <geometry>
          <sphere radius="0.001"/>
        </geometry>
      </collision>
      <inertial>
        <origin rpy="0 0 0" xyz="0 0 0"/>
        <mass value="0.0001"/>
        <inertia ixx="1e-08" ixy="0" ixz="0" iyy="1e-08" iyz="0" izz="1e-08"/>
      </inertial>
    </link>
    <link name="screen">
      <visual>
        <origin rpy="0 -1.57079632679 0" xyz="0 -.00953 -.0347"/>
        <geometry>
          <!-- <box size=".11 0.08  0.01"/> -->
          <mesh filename="package://baxter_description/meshes/head/H1.DAE"/>
        </geometry>
        <material name="darkred">
          <color rgba=".5 .1 .1 1"/>
        </material>
      </visual>
      <collision>
        <origin rpy="0 0 0" xyz="0.0 0 0.0"/>
        <geometry>
          <sphere radius="0.001"/>
        </geometry>
      </collision>
      <inertial>
        <origin rpy="0 0 0" xyz="0 0 0"/>
        <mass value="0.440171"/>
        <inertia ixx="0.004006" ixy="0.000230" ixz="0.000002" iyy="0.002800" iyz="0.000029" izz="0.001509"/>
      </inertial>
    </link>
    <link name="display">
      <visual>
        <origin rpy="0.2617993877991494 0 0" xyz="0 0 0"/>
        <geometry>
          <box size="0.218 0.16 0.001"/>
        </geometry>
        <material name="black">
          <color rgba="0 0 0 1"/>
        </material>
      </visual>
      <inertial>
        <origin rpy="0 0 0" xyz="0 0 0"/>
        <mass value="0.0001"/>
        <inertia ixx="1e-08" ixy="0" ixz="0" iyy="1e-08" iyz="0" izz="1e-08"/>
      </inertial>
    </link>
    <link name="head_camera">
      <inertial>
        <origin rpy="0 0 0" xyz="0 0 0"/>
        <mass value="0.0001"/>
        <inertia ixx="1e-08" ixy="0" ixz="0" iyy="1e-08" iyz="0" izz="1e-08"/>
      </inertial>
    </link>
    <link name="dummyhead1">
      <inertial>
        <origin rpy="0 0 0" xyz="0 0 0"/>
        <mass value="0.0001"/>
        <inertia ixx="1e-08" ixy="0" ixz="0" iyy="1e-08" iyz="0" izz="1e-08"/>
      </inertial>
    </link>
    <link name="collision_head_link_1">
      <visual>
        <origin rpy="0 0 0" xyz="0 0 0"/>
        <geometry>
          <sphere radius="0.001"/>
        </geometry>
        <material name="red">
          <color rgba="0.8 0.3 0.3 0.3"/>
        </material>
      </visual>
      <collision>
        <origin rpy="0 0 0.0" xyz="-0.07 -0.04 0.0"/>
        <geometry>
          <!-- <cylinder radius="0.18" length="0.4" /> -->
          <sphere radius="0.22"/>
        </geometry>
      </collision>
      <inertial>
        <origin rpy="0 0 0" xyz="0 0 0"/>
        <mass value="0.0001"/>
        <inertia ixx="1e-08" ixy="0" ixz="0" iyy="1e-08" iyz="0" izz="1e-08"/>
      </inertial>
    </link>
    <link name="collision_head_link_2">
      <visual>
        <origin rpy="0 0 0" xyz="0 0 0"/>
        <geometry>
          <sphere radius="0.001"/>
        </geometry>
        <material name="red">
          <color rgba="0.8 0.3 0.3 0.3"/>
        </material>
      </visual>
      <collision>
        <!-- <origin xyz="0.0 0.03 0.02" rpy="0 0 0" /> -->
        <origin rpy="0 0 0" xyz="-0.07 0.04 0.00"/>
        <geometry>
          <!-- <box size="0.34 0.27 0.14" /> -->
          <sphere radius="0.22"/>
        </geometry>
      </collision>
      <inertial>
        <origin rpy="0 0 0" xyz="0 0 0"/>
        <mass value="0.0001"/>
        <inertia ixx="1e-08" ixy="0" ixz="0" iyy="1e-08" iyz="0" izz="1e-08"/>
      </inertial>
    </link>
    <joint name="collision_head_1" type="fixed">
      <origin rpy="0 0 0" xyz="0.11 0 0.75"/>
      <parent link="base"/>
      <child link="collision_head_link_1"/>
    </joint>
    <joint name="collision_head_2" type="fixed">
      <origin rpy="0 0 0" xyz="0.11 0 0.75"/>
      <parent link="base"/>
      <child link="collision_head_link_2"/>
    </joint>
    <joint name="dummy" type="fixed">
      <origin rpy="0 0 0" xyz="0 0 0"/>
      <parent link="head"/>
      <child link="dummyhead1"/>
    </joint>
    <joint name="torso_t0" type="fixed">
      <origin rpy="0 0 0" xyz="0 0 0"/>
      <parent link="base"/>
      <child link="torso"/>
      <limit effort="50000" lower="-3.01" upper="3.01" velocity="10000"/>
    </joint>
    <joint name="left_torso_itb_fixed" type="fixed">
      <origin rpy="-1.57079632679 3.1415 0" xyz="-0.08897 0.15593 0.389125"/>
      <parent link="torso"/>
      <child link="left_torso_itb"/>
    </joint>
    <joint name="right_torso_itb_fixed" type="fixed">
      <origin rpy="1.57079632679 0 0" xyz="-0.08897 -0.15593 0.389125"/>
      <parent link="torso"/>
      <child link="right_torso_itb"/>
    </joint>
    <joint name="head_pan" type="revolute">
      <origin rpy="0 0 0" xyz="0.06 0 0.686"/>
      <axis xyz="0 0 1"/>
      <parent link="torso"/>
      <child link="head"/>
      <limit effort="50000" lower="-1.3963" upper="1.3963" velocity="10000"/>
      <dynamics damping="0.7" friction="0.0"/>
    </joint>
    <joint name="head_nod" type="fixed">
      <origin rpy="1.75057 0 1.57079632679" xyz=".1227 0 0"/>
      <parent link="head"/>
      <child link="screen"/>
    </joint>
    <joint name="head_camera" type="fixed">
      <origin rpy="1.75057 0 1.57079632679" xyz="0.12839 0 0.06368"/>
      <parent link="head"/>
      <child link="head_camera"/>
    </joint>
    <joint name="display_joint" type="fixed">
      <origin rpy="0 0 0" xyz="0.0 -0.016 0.0"/>
      <parent link="screen"/>
      <child link="display"/>
    </joint>
    <joint name="sonar_s0" type="fixed">
      <origin rpy="0 0 0" xyz="0.0947 0 .817"/>
      <axis xyz="0 0 1"/>
      <parent link="torso"/>
      <child link="sonar_ring"/>
    </joint>
    <link name="right_arm_mount">
      <!-- all defaults -->
      <inertial>
        <origin rpy="0 0 0" xyz="0 0 0"/>
        <mass value="0.0001"/>
        <inertia ixx="1e-08" ixy="0" ixz="0" iyy="1e-08" iyz="0" izz="1e-08"/>
      </inertial>
    </link>
    <link name="right_upper_shoulder">
      <visual>
        <origin rpy="0 0 0" xyz="0 0 0"/>
        <geometry>
          <mesh filename="package://baxter_description/meshes/upper_shoulder/S0.DAE"/>
        </geometry>
        <material name="darkred">
          <color rgba=".5 .1 .1 1"/>
        </material>
      </visual>
      <collision>
        <origin rpy="0 0 0" xyz="0 0 0.1361"/>
        <geometry>
          <cylinder length="0.2722" radius="0.06"/>
        </geometry>
      </collision>
      <inertial>
        <origin rpy="0 0 0" xyz="0.01783 0.00086 0.19127"/>
        <mass value="5.70044"/>
        <inertia ixx="0.04709102262" ixy="0.00012787556" ixz="0.00614870039" iyy="0.03766976455" iyz="0.00078086899" izz="0.03595988478"/>
      </inertial>
    </link>
    <link name="right_lower_shoulder">
      <visual>
        <origin rpy="0 0 0" xyz="0 0 0"/>
        <geometry>
          <mesh filename="package://baxter_description/meshes/lower_shoulder/S1.DAE"/>
        </geometry>
        <material name="darkred">
          <color rgba=".5 .1 .1 1"/>
        </material>
      </visual>
      <collision>
        <origin rpy="0 0 0" xyz="0 0 0"/>
        <geometry>
          <cylinder length="0.12" radius="0.06"/>
        </geometry>
      </collision>
      <inertial>
        <origin rpy="0 0 0" xyz="0.06845 0.00269 -0.00529"/>
        <mass value="3.22698"/>
        <inertia ixx="0.01175209419" ixy="-0.00030096398" ixz="0.00207675762" iyy="0.0278859752" iyz="-0.00018821993" izz="0.02078749298"/>
      </inertial>
    </link>
    <link name="right_upper_elbow">
      <visual>
        <origin rpy="0 0 0" xyz="0 0 0"/>
        <geometry>
          <mesh filename="package://baxter_description/meshes/upper_elbow/E0.DAE"/>
        </geometry>
        <material name="darkred">
          <color rgba=".5 .1 .1 1"/>
        </material>
      </visual>
      <collision>
        <origin rpy="0 0 0" xyz="0 0 -0.0535"/>
        <geometry>
          <cylinder length="0.107" radius="0.06"/>
        </geometry>
      </collision>
      <inertial>
        <origin rpy="0 0 0" xyz="-0.00276 0.00132 0.18086"/>
        <mass value="4.31272"/>
        <inertia ixx="0.02661733557" ixy="0.00029270634" ixz="0.00392189887" iyy="0.02844355207" iyz="0.0010838933" izz="0.01248008322"/>
      </inertial>
    </link>
    <link name="right_upper_elbow_visual">
      <collision>
        <origin rpy="0 0 0" xyz="0 0 0.1365"/>
        <geometry>
          <cylinder length="0.273" radius="0.06"/>
        </geometry>
      </collision>
      <inertial>
        <origin rpy="0 0 0" xyz="0 0 0"/>
        <mass value="0.0001"/>
        <inertia ixx="1e-08" ixy="0" ixz="0" iyy="1e-08" iyz="0" izz="1e-08"/>
      </inertial>
    </link>
    <link name="right_lower_elbow">
      <visual>
        <origin rpy="0 0 0" xyz="0 0 0"/>
        <geometry>
          <mesh filename="package://baxter_description/meshes/lower_elbow/E1.DAE"/>
        </geometry>
        <material name="darkred">
          <color rgba=".5 .1 .1 1"/>
        </material>
      </visual>
      <collision>
        <origin rpy="0 0 0" xyz="0.0 0.0 0.0"/>
        <geometry>
          <cylinder length="0.10" radius="0.06"/>
        </geometry>
      </collision>
      <inertial>
        <origin rpy="0 0 0" xyz="0.02611 0.00159 -0.01117"/>
        <mass value="2.07206"/>
        <inertia ixx="0.00711582686" ixy="0.00036036173" ixz="0.0007459496" iyy="0.01318227876" iyz="-0.00019663418" izz="0.00926852064"/>
      </inertial>
    </link>
    <link name="right_upper_forearm">
      <visual>
        <origin rpy="0 0 0" xyz="0 0 0"/>
        <geometry>
          <mesh filename="package://baxter_description/meshes/upper_forearm/W0.DAE"/>
        </geometry>
        <material name="darkred">
          <color rgba=".5 .1 .1 1"/>
        </material>
      </visual>
      <collision>
        <origin rpy="0 0 0" xyz="0 0 -0.044"/>
        <geometry>
          <cylinder length="0.088" radius="0.06"/>
        </geometry>
      </collision>
      <inertial>
        <origin rpy="0 0 0" xyz="-0.00168 0.0046 0.13952"/>
        <mass value="2.24665"/>
        <inertia ixx="0.01667742825" ixy="0.00018403705" ixz="0.00018657629" iyy="0.01675457264" iyz="-0.00064732352" izz="0.0037463115"/>
      </inertial>
    </link>
    <link name="right_upper_forearm_visual">
      <collision>
        <origin rpy="0 0 0" xyz="0 0 0.136"/>
        <geometry>
          <cylinder length="0.272" radius="0.06"/>
        </geometry>
      </collision>
      <inertial>
        <origin rpy="0 0 0" xyz="0 0 0"/>
        <mass value="0.0001"/>
        <inertia ixx="1e-08" ixy="0" ixz="0" iyy="1e-08" iyz="0" izz="1e-08"/>
      </inertial>
    </link>
    <link name="right_arm_itb">
      <!-- note: invisible -->
      <!--
           <visual>
             <origin xyz="0 0 0" rpy="0 0 0" />
             <geometry>
               <box size=".059 0.118  0.032" />
             </geometry>
             <material name="white">
               <color rgba="1 1 1 1" />
             </material>
           </visual>
           -->
      <inertial>
        <origin rpy="0 0 0" xyz="0.000000 0.000000 0.000000"/>
        <mass value="0.0001"/>
        <inertia ixx="1e-08" ixy="0" ixz="0" iyy="1e-08" iyz="0" izz="1e-08"/>
      </inertial>
    </link>
    <link name="right_lower_forearm">
      <visual>
        <origin rpy="0 0 0" xyz="0 0 0"/>
        <geometry>
          <mesh filename="package://baxter_description/meshes/lower_forearm/W1.DAE"/>
        </geometry>
        <material name="darkred">
          <color rgba=".5 .1 .1 1"/>
        </material>
      </visual>
      <collision>
        <origin rpy="0 0 0" xyz="0 0 0"/>
        <geometry>
          <cylinder length="0.10" radius="0.06"/>
        </geometry>
      </collision>
      <inertial>
        <origin rpy="0 0 0" xyz="0.06041 0.00697 0.006"/>
        <mass value="1.60979"/>
        <inertia ixx="0.00387607152" ixy="-0.00044384784" ixz="-0.00021115038" iyy="0.00700537914" iyz="0.00015348067" izz="0.0055275524"/>
      </inertial>
    </link>
    <link name="right_wrist">
      <visual>
        <origin rpy="0 0 0" xyz="0 0 0"/>
        <geometry>
          <mesh filename="package://baxter_description/meshes/wrist/W2.DAE"/>
        </geometry>
        <material name="lightgrey">
          <color rgba=".1 .1 .1 1"/>
        </material>
      </visual>
      <collision>
        <origin rpy="0 0 0" xyz="0 0 0"/>
        <geometry>
          <cylinder length="0.165" radius="0.06"/>
        </geometry>
      </collision>
      <inertial>
        <origin rpy="0 0 0" xyz="0.00198 0.00125 0.01855"/>
        <mass value="0.35093"/>
        <inertia ixx="0.00025289155" ixy="0.00000575311" ixz="-0.00000159345" iyy="0.0002688601" iyz="-0.00000519818" izz="0.0003074118"/>
      </inertial>
    </link>
    <link name="right_hand">
      <!-- rendered in the mesh
        <visual>
          <origin xyz="0 0 -0.0232" rpy="0 0 0" />
          <geometry>
            <cylinder radius="0.04" length="0.0464" />
          </geometry>
          <material name="darkred">
            <color rgba=".5 .1 .1 1" />
          </material>
        </visual>
        -->
      <collision>
        <origin rpy="0 0 0" xyz="0 0 -0.0232"/>
        <geometry>
          <cylinder length="0.0464" radius="0.04"/>
        </geometry>
      </collision>
      <inertial>
        <origin rpy="0 0 0" xyz="0.01093 0.00042 -0.01532"/>
        <mass value="0.19125"/>
        <inertia ixx="0.00017588" ixy="0.00000147073" ixz="0.0000243633" iyy="0.00021166377" iyz="0.00000172689" izz="0.00023745397"/>
      </inertial>
    </link>
    <link name="right_hand_camera">
      <visual>
        <origin rpy="0 0 0" xyz="0 0 0"/>
        <geometry>
          <cylinder length="0.01" radius="0.02"/>
        </geometry>
        <material name="blue">
          <color rgba="0 0 1 0.8"/>
        </material>
      </visual>
      <inertial>
        <origin rpy="0 0 0" xyz="0 0 0"/>
        <mass value="0.0001"/>
        <inertia ixx="1e-08" ixy="0" ixz="0" iyy="1e-08" iyz="0" izz="1e-08"/>
      </inertial>
    </link>
    <link name="right_hand_camera_axis">
      <!--visual>
          <origin xyz="0 0 0" rpy="0 0 0" />
          <geometry>
            <cylinder radius="0.02" length="0.01" />
          </geometry>
          <material name="blue">
            <color rgba="0 0 1 0.8" />
          </material>
        </visual-->
      <inertial>
        <origin rpy="0 0 0" xyz="0 0 0"/>
        <mass value="0.0001"/>
        <inertia ixx="1e-08" ixy="0" ixz="0" iyy="1e-08" iyz="0" izz="1e-08"/>
      </inertial>
    </link>
    <link name="right_hand_range">
      <visual>
        <origin rpy="0 0 0" xyz="0 0 0"/>
        <geometry>
          <box size="0.005 .02 .005"/>
        </geometry>
        <material name="blue">
          <color rgba="0 0 1 0.8"/>
        </material>
      </visual>
      <inertial>
        <origin rpy="0 0 0" xyz="0 0 0"/>
        <mass value="0.0001"/>
        <inertia ixx="1e-08" ixy="0" ixz="0" iyy="1e-08" iyz="0" izz="1e-08"/>
      </inertial>
    </link>
    <link name="right_hand_accelerometer">
      <visual>
        <origin rpy="0 0 0" xyz="0 0 0"/>
        <geometry>
          <box size="0.01 0.01 0.01"/>
        </geometry>
        <material name="black">
          <color rgba="0 0 0 1"/>
        </material>
      </visual>
      <inertial>
        <origin rpy="0 0 0" xyz="0.000000 0.000000 0.000000"/>
        <mass value="0.0001"/>
        <inertia ixx="1e-08" ixy="0" ixz="0" iyy="1e-08" iyz="0" izz="1e-08"/>
      </inertial>
    </link>
    <joint name="right_torso_arm_mount" type="fixed">
      <origin rpy="-0.00186901707751 0.00254393188156 -0.784699662277" xyz="0.0243659438693 -0.219949946002 0.108955294841"/>
      <parent link="torso"/>
      <child link="right_arm_mount"/>
    </joint>
    <joint name="right_s0" type="revolute">
      <origin rpy="0 0 0" xyz="0.055695 0 0.011038"/>
      <axis xyz="0 0 1"/>
      <parent link="right_arm_mount"/>
      <child link="right_upper_shoulder"/>
      <limit effort="50.0" lower="-1.70167993878" upper="1.70167993878" velocity="1.5"/>
      <dynamics damping="0.7" friction="0.0"/>
    </joint>
    <joint name="right_s1" type="revolute">
      <origin rpy="-1.57079632679 0 0" xyz="0.069 0 0.27035"/>
      <axis xyz="0 0 1"/>
      <parent link="right_upper_shoulder"/>
      <child link="right_lower_shoulder"/>
      <limit effort="50.0" lower="-2.147" upper="1.047" velocity="1.5"/>
      <dynamics damping="0.7" friction="0.0"/>
    </joint>
    <joint name="right_e0" type="revolute">
      <origin rpy="1.57079632679 0 1.57079632679" xyz="0.102 0 0"/>
      <axis xyz="0 0 1"/>
      <parent link="right_lower_shoulder"/>
      <child link="right_upper_elbow"/>
      <limit effort="50.0" lower="-3.05417993878" upper="3.05417993878" velocity="1.5"/>
      <dynamics damping="0.7" friction="0.0"/>
    </joint>
    <joint name="right_e0_fixed" type="fixed">
      <origin rpy="1.57079632679 0 1.57079632679" xyz="0.107 0 0"/>
      <axis xyz="0 0 1"/>
      <parent link="right_lower_shoulder"/>
      <child link="right_upper_elbow_visual"/>
    </joint>
    <joint name="right_e1" type="revolute">
      <origin rpy="-1.57079632679 -1.57079632679 0" xyz="0.069 0 0.26242"/>
      <axis xyz="0 0 1"/>
      <parent link="right_upper_elbow"/>
      <child link="right_lower_elbow"/>
      <limit effort="50.0" lower="-0.05" upper="2.618" velocity="1.5"/>
      <dynamics damping="0.7" friction="0.0"/>
    </joint>
    <joint name="right_w0" type="revolute">
      <origin rpy="1.57079632679 0 1.57079632679" xyz="0.10359 0 0"/>
      <axis xyz="0 0 1"/>
      <parent link="right_lower_elbow"/>
      <child link="right_upper_forearm"/>
      <limit effort="15.0" lower="-3.059" upper="3.059" velocity="4.0"/>
      <dynamics damping="0.7" friction="0.0"/>
    </joint>
    <joint name="right_w0_fixed" type="fixed">
      <origin rpy="1.57079632679 0 1.57079632679" xyz="0.088 0 0"/>
      <axis xyz="0 0 1"/>
      <parent link="right_lower_elbow"/>
      <child link="right_upper_forearm_visual"/>
    </joint>
    <joint name="right_w0_to_itb_fixed" type="fixed">
      <origin rpy="-1.57079632679 0 1.57079632679" xyz="-0.0565 0 0.12"/>
      <axis xyz="0 0 1"/>
      <parent link="right_upper_forearm"/>
      <child link="right_arm_itb"/>
    </joint>
    <joint name="right_w1" type="revolute">
      <origin rpy="-1.57079632679 -1.57079632679 0" xyz="0.01 0 0.2707"/>
      <axis xyz="0 0 1"/>
      <parent link="right_upper_forearm"/>
      <child link="right_lower_forearm"/>
      <limit effort="15.0" lower="-1.57079632679" upper="2.094" velocity="4.0"/>
      <dynamics damping="0.7" friction="0.0"/>
    </joint>
    <joint name="right_w2" type="revolute">
      <origin rpy="1.57079632679 0 1.57079632679" xyz="0.115975 0 0"/>
      <axis xyz="0 0 1"/>
      <parent link="right_lower_forearm"/>
      <child link="right_wrist"/>
      <limit effort="15.0" lower="-3.059" upper="3.059" velocity="4.0"/>
      <dynamics damping="0.7" friction="0.0"/>
    </joint>
    <joint name="right_hand" type="fixed">
      <origin rpy="0 0 0" xyz="0 0 0.11355"/>
      <axis xyz="0 0 1"/>
      <parent link="right_wrist"/>
      <child link="right_hand"/>
    </joint>
    <joint name="right_hand_camera" type="fixed">
      <origin rpy="0 0 -1.57079633" xyz="0.03825 0.012 0.015355"/>
      <parent link="right_hand"/>
      <child link="right_hand_camera"/>
    </joint>
    <joint name="right_hand_camera_axis" type="fixed">
      <origin rpy="0 0 0" xyz="0.03825 0.012 0.015355"/>
      <parent link="right_hand"/>
      <child link="right_hand_camera_axis"/>
    </joint>
    <joint name="right_hand_range" type="fixed">
      <origin rpy="0 -1.57079632679 -1.57079632679" xyz="0.032 -0.020245 0.0288"/>
      <parent link="right_hand"/>
      <child link="right_hand_range"/>
    </joint>
    <joint name="right_hand_accelerometer" type="fixed">
      <origin rpy="0 0 0" xyz="0.00198 0.000133 -0.0146"/>
      <parent link="right_hand"/>
      <child link="right_hand_accelerometer"/>
    </joint>
    <link name="left_arm_mount">
      <!-- all defaults -->
      <inertial>
        <origin rpy="0 0 0" xyz="0 0 0"/>
        <mass value="0.0001"/>
        <inertia ixx="1e-08" ixy="0" ixz="0" iyy="1e-08" iyz="0" izz="1e-08"/>
      </inertial>
    </link>
    <link name="left_upper_shoulder">
      <visual>
        <origin rpy="0 0 0" xyz="0 0 0"/>
        <geometry>
          <mesh filename="package://baxter_description/meshes/upper_shoulder/S0.DAE"/>
        </geometry>
        <material name="darkred">
          <color rgba=".5 .1 .1 1"/>
        </material>
      </visual>
      <collision>
        <origin rpy="0 0 0" xyz="0 0 0.1361"/>
        <geometry>
          <cylinder length="0.2722" radius="0.06"/>
        </geometry>
      </collision>
      <inertial>
        <origin rpy="0 0 0" xyz="0.01783 0.00086 0.19127"/>
        <mass value="5.70044"/>
        <inertia ixx="0.04709102262" ixy="0.00012787556" ixz="0.00614870039" iyy="0.03766976455" iyz="0.00078086899" izz="0.03595988478"/>
      </inertial>
    </link>
    <link name="left_lower_shoulder">
      <visual>
        <origin rpy="0 0 0" xyz="0 0 0"/>
        <geometry>
          <mesh filename="package://baxter_description/meshes/lower_shoulder/S1.DAE"/>
        </geometry>
        <material name="darkred">
          <color rgba=".5 .1 .1 1"/>
        </material>
      </visual>
      <collision>
        <origin rpy="0 0 0" xyz="0 0 0"/>
        <geometry>
          <cylinder length="0.12" radius="0.06"/>
        </geometry>
      </collision>
      <inertial>
        <origin rpy="0 0 0" xyz="0.06845 0.00269 -0.00529"/>
        <mass value="3.22698"/>
        <inertia ixx="0.01175209419" ixy="-0.00030096398" ixz="0.00207675762" iyy="0.0278859752" iyz="-0.00018821993" izz="0.02078749298"/>
      </inertial>
    </link>
    <link name="left_upper_elbow">
      <visual>
        <origin rpy="0 0 0" xyz="0 0 0"/>
        <geometry>
          <mesh filename="package://baxter_description/meshes/upper_elbow/E0.DAE"/>
        </geometry>
        <material name="darkred">
          <color rgba=".5 .1 .1 1"/>
        </material>
      </visual>
      <collision>
        <origin rpy="0 0 0" xyz="0 0 -0.0535"/>
        <geometry>
          <cylinder length="0.107" radius="0.06"/>
        </geometry>
      </collision>
      <inertial>
        <origin rpy="0 0 0" xyz="-0.00276 0.00132 0.18086"/>
        <mass value="4.31272"/>
        <inertia ixx="0.02661733557" ixy="0.00029270634" ixz="0.00392189887" iyy="0.02844355207" iyz="0.0010838933" izz="0.01248008322"/>
      </inertial>
    </link>
    <link name="left_upper_elbow_visual">
      <collision>
        <origin rpy="0 0 0" xyz="0 0 0.1365"/>
        <geometry>
          <cylinder length="0.273" radius="0.06"/>
        </geometry>
      </collision>
      <inertial>
        <origin rpy="0 0 0" xyz="0 0 0"/>
        <mass value="0.0001"/>
        <inertia ixx="1e-08" ixy="0" ixz="0" iyy="1e-08" iyz="0" izz="1e-08"/>
      </inertial>
    </link>
    <link name="left_lower_elbow">
      <visual>
        <origin rpy="0 0 0" xyz="0 0 0"/>
        <geometry>
          <mesh filename="package://baxter_description/meshes/lower_elbow/E1.DAE"/>
        </geometry>
        <material name="darkred">
          <color rgba=".5 .1 .1 1"/>
        </material>
      </visual>
      <collision>
        <origin rpy="0 0 0" xyz="0.0 0.0 0.0"/>
        <geometry>
          <cylinder length="0.10" radius="0.06"/>
        </geometry>
      </collision>
      <inertial>
        <origin rpy="0 0 0" xyz="0.02611 0.00159 -0.01117"/>
        <mass value="2.07206"/>
        <inertia ixx="0.00711582686" ixy="0.00036036173" ixz="0.0007459496" iyy="0.01318227876" iyz="-0.00019663418" izz="0.00926852064"/>
      </inertial>
    </link>
    <link name="left_upper_forearm">
      <visual>
        <origin rpy="0 0 0" xyz="0 0 0"/>
        <geometry>
          <mesh filename="package://baxter_description/meshes/upper_forearm/W0.DAE"/>
        </geometry>
        <material name="darkred">
          <color rgba=".5 .1 .1 1"/>
        </material>
      </visual>
      <collision>
        <origin rpy="0 0 0" xyz="0 0 -0.044"/>
        <geometry>
          <cylinder length="0.088" radius="0.06"/>
        </geometry>
      </collision>
      <inertial>
        <origin rpy="0 0 0" xyz="-0.00168 0.0046 0.13952"/>
        <mass value="2.24665"/>
        <inertia ixx="0.01667742825" ixy="0.00018403705" ixz="0.00018657629" iyy="0.01675457264" iyz="-0.00064732352" izz="0.0037463115"/>
      </inertial>
    </link>
    <link name="left_upper_forearm_visual">
      <collision>
        <origin rpy="0 0 0" xyz="0 0 0.136"/>
        <geometry>
          <cylinder length="0.272" radius="0.06"/>
        </geometry>
      </collision>
      <inertial>
        <origin rpy="0 0 0" xyz="0 0 0"/>
        <mass value="0.0001"/>
        <inertia ixx="1e-08" ixy="0" ixz="0" iyy="1e-08" iyz="0" izz="1e-08"/>
      </inertial>
    </link>
    <link name="left_arm_itb">
      <!-- note: invisible -->
      <!--
           <visual>
             <origin xyz="0 0 0" rpy="0 0 0" />
             <geometry>
               <box size=".059 0.118  0.032" />
             </geometry>
             <material name="white">
               <color rgba="1 1 1 1" />
             </material>
           </visual>
           -->
      <inertial>
        <origin rpy="0 0 0" xyz="0.000000 0.000000 0.000000"/>
        <mass value="0.0001"/>
        <inertia ixx="1e-08" ixy="0" ixz="0" iyy="1e-08" iyz="0" izz="1e-08"/>
      </inertial>
    </link>
    <link name="left_lower_forearm">
      <visual>
        <origin rpy="0 0 0" xyz="0 0 0"/>
        <geometry>
          <mesh filename="package://baxter_description/meshes/lower_forearm/W1.DAE"/>
        </geometry>
        <material name="darkred">
          <color rgba=".5 .1 .1 1"/>
        </material>
      </visual>
      <collision>
        <origin rpy="0 0 0" xyz="0 0 0"/>
        <geometry>
          <cylinder length="0.10" radius="0.06"/>
        </geometry>
      </collision>
      <inertial>
        <origin rpy="0 0 0" xyz="0.06041 0.00697 0.006"/>
        <mass value="1.60979"/>
        <inertia ixx="0.00387607152" ixy="-0.00044384784" ixz="-0.00021115038" iyy="0.00700537914" iyz="0.00015348067" izz="0.0055275524"/>
      </inertial>
    </link>
    <link name="left_wrist">
      <visual>
        <origin rpy="0 0 0" xyz="0 0 0"/>
        <geometry>
          <mesh filename="package://baxter_description/meshes/wrist/W2.DAE"/>
        </geometry>
        <material name="lightgrey">
          <color rgba=".1 .1 .1 1"/>
        </material>
      </visual>
      <collision>
        <origin rpy="0 0 0" xyz="0 0 0"/>
        <geometry>
          <cylinder length="0.165" radius="0.06"/>
        </geometry>
      </collision>
      <inertial>
        <origin rpy="0 0 0" xyz="0.00198 0.00125 0.01855"/>
        <mass value="0.35093"/>
        <inertia ixx="0.00025289155" ixy="0.00000575311" ixz="-0.00000159345" iyy="0.0002688601" iyz="-0.00000519818" izz="0.0003074118"/>
      </inertial>
    </link>
    <link name="left_hand">
      <!-- rendered in the mesh
        <visual>
          <origin xyz="0 0 -0.0232" rpy="0 0 0" />
          <geometry>
            <cylinder radius="0.04" length="0.0464" />
          </geometry>
          <material name="darkred">
            <color rgba=".5 .1 .1 1" />
          </material>
        </visual>
        -->
      <collision>
        <origin rpy="0 0 0" xyz="0 0 -0.0232"/>
        <geometry>
          <cylinder length="0.0464" radius="0.04"/>
        </geometry>
      </collision>
      <inertial>
        <origin rpy="0 0 0" xyz="0.01093 0.00042 -0.01532"/>
        <mass value="0.19125"/>
        <inertia ixx="0.00017588" ixy="0.00000147073" ixz="0.0000243633" iyy="0.00021166377" iyz="0.00000172689" izz="0.00023745397"/>
      </inertial>
    </link>
    <link name="left_hand_camera">
      <visual>
        <origin rpy="0 0 0" xyz="0 0 0"/>
        <geometry>
          <cylinder length="0.01" radius="0.02"/>
        </geometry>
        <material name="blue">
          <color rgba="0 0 1 0.8"/>
        </material>
      </visual>
      <inertial>
        <origin rpy="0 0 0" xyz="0 0 0"/>
        <mass value="0.0001"/>
        <inertia ixx="1e-08" ixy="0" ixz="0" iyy="1e-08" iyz="0" izz="1e-08"/>
      </inertial>
    </link>
    <link name="left_hand_camera_axis">
      <!--visual>
          <origin xyz="0 0 0" rpy="0 0 0" />
          <geometry>
            <cylinder radius="0.02" length="0.01" />
          </geometry>
          <material name="blue">
            <color rgba="0 0 1 0.8" />
          </material>
        </visual-->
      <inertial>
        <origin rpy="0 0 0" xyz="0 0 0"/>
        <mass value="0.0001"/>
        <inertia ixx="1e-08" ixy="0" ixz="0" iyy="1e-08" iyz="0" izz="1e-08"/>
      </inertial>
    </link>
    <link name="left_hand_range">
      <visual>
        <origin rpy="0 0 0" xyz="0 0 0"/>
        <geometry>
          <box size="0.005 .02 .005"/>
        </geometry>
        <material name="blue">
          <color rgba="0 0 1 0.8"/>
        </material>
      </visual>
      <inertial>
        <origin rpy="0 0 0" xyz="0 0 0"/>
        <mass value="0.0001"/>
        <inertia ixx="1e-08" ixy="0" ixz="0" iyy="1e-08" iyz="0" izz="1e-08"/>
      </inertial>
    </link>
    <link name="left_hand_accelerometer">
      <visual>
        <origin rpy="0 0 0" xyz="0 0 0"/>
        <geometry>
          <box size="0.01 0.01 0.01"/>
        </geometry>
        <material name="black">
          <color rgba="0 0 0 1"/>
        </material>
      </visual>
      <inertial>
        <origin rpy="0 0 0" xyz="0.000000 0.000000 0.000000"/>
        <mass value="0.0001"/>
        <inertia ixx="1e-08" ixy="0" ixz="0" iyy="1e-08" iyz="0" izz="1e-08"/>
      </inertial>
    </link>
    <joint name="left_torso_arm_mount" type="fixed">
      <origin rpy="0.000778625747733 -0.00202340949972 0.779541995313" xyz="0.0256151855005 0.219408971619 0.108217894885"/>
      <parent link="torso"/>
      <child link="left_arm_mount"/>
    </joint>
    <joint name="left_s0" type="revolute">
      <origin rpy="0 0 0" xyz="0.055695 0 0.011038"/>
      <axis xyz="0 0 1"/>
      <parent link="left_arm_mount"/>
      <child link="left_upper_shoulder"/>
      <limit effort="50.0" lower="-1.70167993878" upper="1.70167993878" velocity="1.5"/>
      <dynamics damping="0.7" friction="0.0"/>
    </joint>
    <joint name="left_s1" type="revolute">
      <origin rpy="-1.57079632679 0 0" xyz="0.069 0 0.27035"/>
      <axis xyz="0 0 1"/>
      <parent link="left_upper_shoulder"/>
      <child link="left_lower_shoulder"/>
      <limit effort="50.0" lower="-2.147" upper="1.047" velocity="1.5"/>
      <dynamics damping="0.7" friction="0.0"/>
    </joint>
    <joint name="left_e0" type="revolute">
      <origin rpy="1.57079632679 0 1.57079632679" xyz="0.102 0 0"/>
      <axis xyz="0 0 1"/>
      <parent link="left_lower_shoulder"/>
      <child link="left_upper_elbow"/>
      <limit effort="50.0" lower="-3.05417993878" upper="3.05417993878" velocity="1.5"/>
      <dynamics damping="0.7" friction="0.0"/>
    </joint>
    <joint name="left_e0_fixed" type="fixed">
      <origin rpy="1.57079632679 0 1.57079632679" xyz="0.107 0 0"/>
      <axis xyz="0 0 1"/>
      <parent link="left_lower_shoulder"/>
      <child link="left_upper_elbow_visual"/>
    </joint>
    <joint name="left_e1" type="revolute">
      <origin rpy="-1.57079632679 -1.57079632679 0" xyz="0.069 0 0.26242"/>
      <axis xyz="0 0 1"/>
      <parent link="left_upper_elbow"/>
      <child link="left_lower_elbow"/>
      <limit effort="50.0" lower="-0.05" upper="2.618" velocity="1.5"/>
      <dynamics damping="0.7" friction="0.0"/>
    </joint>
    <joint name="left_w0" type="revolute">
      <origin rpy="1.57079632679 0 1.57079632679" xyz="0.10359 0 0"/>
      <axis xyz="0 0 1"/>
      <parent link="left_lower_elbow"/>
      <child link="left_upper_forearm"/>
      <limit effort="15.0" lower="-3.059" upper="3.059" velocity="4.0"/>
      <dynamics damping="0.7" friction="0.0"/>
    </joint>
    <joint name="left_w0_fixed" type="fixed">
      <origin rpy="1.57079632679 0 1.57079632679" xyz="0.088 0 0"/>
      <axis xyz="0 0 1"/>
      <parent link="left_lower_elbow"/>
      <child link="left_upper_forearm_visual"/>
    </joint>
    <joint name="left_w0_to_itb_fixed" type="fixed">
      <origin rpy="-1.57079632679 0 1.57079632679" xyz="-0.0565 0 0.12"/>
      <axis xyz="0 0 1"/>
      <parent link="left_upper_forearm"/>
      <child link="left_arm_itb"/>
    </joint>
    <joint name="left_w1" type="revolute">
      <origin rpy="-1.57079632679 -1.57079632679 0" xyz="0.01 0 0.2707"/>
      <axis xyz="0 0 1"/>
      <parent link="left_upper_forearm"/>
      <child link="left_lower_forearm"/>
      <limit effort="15.0" lower="-1.57079632679" upper="2.094" velocity="4.0"/>
      <dynamics damping="0.7" friction="0.0"/>
    </joint>
    <joint name="left_w2" type="revolute">
      <origin rpy="1.57079632679 0 1.57079632679" xyz="0.115975 0 0"/>
      <axis xyz="0 0 1"/>
      <parent link="left_lower_forearm"/>
      <child link="left_wrist"/>
      <limit effort="15.0" lower="-3.059" upper="3.059" velocity="4.0"/>
      <dynamics damping="0.7" friction="0.0"/>
    </joint>
    <joint name="left_hand" type="fixed">
      <origin rpy="0 0 0" xyz="0 0 0.11355"/>
      <axis xyz="0 0 1"/>
      <parent link="left_wrist"/>
      <child link="left_hand"/>
    </joint>
    <joint name="left_hand_camera" type="fixed">
      <origin rpy="0 0 -1.57079633" xyz="0.03825 0.012 0.015355"/>
      <parent link="left_hand"/>
      <child link="left_hand_camera"/>
    </joint>
    <joint name="left_hand_camera_axis" type="fixed">
      <origin rpy="0 0 0" xyz="0.03825 0.012 0.015355"/>
      <parent link="left_hand"/>
      <child link="left_hand_camera_axis"/>
    </joint>
    <joint name="left_hand_range" type="fixed">
      <origin rpy="0 -1.57079632679 -1.57079632679" xyz="0.032 -0.020245 0.0288"/>
      <parent link="left_hand"/>
      <child link="left_hand_range"/>
    </joint>
    <joint name="left_hand_accelerometer" type="fixed">
      <origin rpy="0 0 0" xyz="0.00198 0.000133 -0.0146"/>
      <parent link="left_hand"/>
      <child link="left_hand_accelerometer"/>
    </joint>
  
    <!-- Base of end effector -->
    <link name="left_gripper_base">
      <visual>
        <origin rpy="-1.57079632679 3.14159265359 0" xyz="0 0 0"/>
        <geometry>
          <mesh filename="package://rethink_ee_description/meshes/electric_gripper/electric_gripper_base.DAE"/>
        </geometry>
      </visual>
      <collision>
        <origin rpy="-1.57079632679 3.14159265359 0" xyz="0.0 0.0 0"/>
        <geometry>
          <cylinder length="0.1" radius="0.029"/>
        </geometry>
        <material name="darkred">
          <color rgba=".5 .1 .1 1"/>
        </material>
      </collision>
      <inertial>
        <origin rpy="-1.57079632679 3.14159265359 0" xyz="0.0 0.0 0.0"/>
        <mass value="0.3"/>
        <inertia ixx="2e-08" ixy="0" ixz="0" iyy="3e-08" iyz="0" izz="2e-08"/>
      </inertial>
    </link>
    <link name="l_gripper_l_finger">
      <visual>
        <origin rpy="0 0 -3.14159265359" xyz="0 0 0"/>
        <geometry>
          <mesh filename="package://rethink_ee_description/meshes/electric_gripper/fingers/standard_narrow.DAE"/>
        </geometry>
      </visual>
      <collision>
        <origin rpy="0 0 -3.14159265359" xyz="0 0.01725 0.04"/>
        <geometry>
          <box size="0.01 0.0135 0.075"/>
        </geometry>
      </collision>
      <collision>
        <origin rpy="0 0 -3.14159265359" xyz="-0.005 -0.003 0.0083"/>
        <geometry>
          <box size="0.01 0.05 0.017"/>
        </geometry>
      </collision>
      <inertial>
        <origin rpy="0 0 -3.14159265359" xyz="0 0 0"/>
        <mass value="0.02"/>
        <inertia ixx="0.01" ixy="0" ixz="0" iyy="0.01" iyz="0" izz="0.01"/>
      </inertial>
    </link>
    <gazebo reference="l_gripper_l_finger">
      <mu1>1000</mu1>
      <mu2>1000</mu2>
      <fdir1>0.0 0.0 1.0</fdir1>
      <kp>1e5</kp>
      <kd>1.0</kd>
    </gazebo>
    <link name="l_gripper_l_finger_tip">
      <visual>
        <origin rpy="0 0 3.14159265359" xyz="0 0 0"/>
        <geometry>
          <mesh filename="package://rethink_ee_description/meshes/electric_gripper/fingers/half_round_tip.DAE"/>
        </geometry>
      </visual>
      <collision>
        <origin rpy="0 0 3.14159265359" xyz="0 -0.0045 -0.015"/>
        <geometry>
          <cylinder length="0.037" radius="0.008"/>
        </geometry>
      </collision>
      <inertial>
        <origin rpy="0 0 3.14159265359" xyz="0 0 0"/>
        <mass value="0.01"/>
        <inertia ixx="0.01" ixy="0" ixz="0" iyy="0.01" iyz="0" izz="0.01"/>
      </inertial>
    </link>
    <joint name="l_gripper_l_finger_tip_joint" type="fixed">
      <origin rpy="0 0 0" xyz="0.0 0.01725 0.075"/>
      <parent link="l_gripper_l_finger"/>
      <child link="l_gripper_l_finger_tip"/>
    </joint>
    <link name="l_gripper_r_finger">
      <visual>
        <origin rpy="0 0 -0.0" xyz="0 0 0"/>
        <geometry>
          <mesh filename="package://rethink_ee_description/meshes/electric_gripper/fingers/standard_narrow.DAE"/>
        </geometry>
      </visual>
      <collision>
        <origin rpy="0 0 -0.0" xyz="0 -0.01725 0.04"/>
        <geometry>
          <box size="0.01 0.0135 0.075"/>
        </geometry>
      </collision>
      <collision>
        <origin rpy="0 0 -0.0" xyz="0.005 0.003 0.0083"/>
        <geometry>
          <box size="0.01 0.05 0.017"/>
        </geometry>
      </collision>
      <inertial>
        <origin rpy="0 0 -0.0" xyz="0 0 0"/>
        <mass value="0.02"/>
        <inertia ixx="0.01" ixy="0" ixz="0" iyy="0.01" iyz="0" izz="0.01"/>
      </inertial>
    </link>
    <gazebo reference="l_gripper_r_finger">
      <mu1>1000</mu1>
      <mu2>1000</mu2>
      <fdir1>0.0 0.0 1.0</fdir1>
      <kp>1e5</kp>
      <kd>1.0</kd>
    </gazebo>
    <link name="l_gripper_r_finger_tip">
      <visual>
        <origin rpy="0 0 0.0" xyz="0 0 0"/>
        <geometry>
          <mesh filename="package://rethink_ee_description/meshes/electric_gripper/fingers/half_round_tip.DAE"/>
        </geometry>
      </visual>
      <collision>
        <origin rpy="0 0 0.0" xyz="0 0.0045 -0.015"/>
        <geometry>
          <cylinder length="0.037" radius="0.008"/>
        </geometry>
      </collision>
      <inertial>
        <origin rpy="0 0 0.0" xyz="0 0 0"/>
        <mass value="0.01"/>
        <inertia ixx="0.01" ixy="0" ixz="0" iyy="0.01" iyz="0" izz="0.01"/>
      </inertial>
    </link>
    <joint name="l_gripper_r_finger_tip_joint" type="fixed">
      <origin rpy="0 0 0" xyz="0.0 -0.01725 0.075"/>
      <parent link="l_gripper_r_finger"/>
      <child link="l_gripper_r_finger_tip"/>
    </joint>
    <!-- Electric Gripper Base Joint -->
    <joint name="left_gripper_base" type="fixed">
      <origin rpy="0 0 0" xyz="0 0 0.025"/>
      <parent link="left_hand"/>
      <child link="left_gripper_base"/>
    </joint>
    <!-- Electric Gripper Tip joint -->
    <joint name="left_endpoint" type="fixed">
      <origin rpy="0 0 0" xyz="0 0 0.095"/>
      <parent link="left_gripper_base"/>
      <child link="left_gripper"/>
    </joint>
    <!-- Electric Gripper Tip link -->
    <link name="left_gripper">
      <inertial>
        <origin rpy="0 0 0" xyz="0 0 0"/>
        <mass value="0.0001"/>
        <inertia ixx="0" ixy="0" ixz="0" iyy="0" iyz="0" izz="0.0"/>
      </inertial>
    </link>
    <joint name="l_gripper_l_finger_joint" type="prismatic">
      <origin rpy="0 0 0" xyz="0.0 0.0365 0.02"/>
      <axis xyz="0 1 0"/>
      <parent link="left_gripper_base"/>
      <child link="l_gripper_l_finger"/>
      <limit effort="20.0" lower="0.0" upper="0.020833" velocity="5.0"/>
      <dynamics damping="0.7" friction="0.0"/>
    </joint>
    <joint name="l_gripper_r_finger_joint" type="prismatic">
      <origin rpy="0 0 0" xyz="0.0 -0.0175 0.02"/>
      <axis xyz="0 1 0"/>
      <parent link="left_gripper_base"/>
      <child link="l_gripper_r_finger"/>
      <limit effort="20.0" lower="-0.020833" upper="0.0" velocity="5.0"/>
      <mimic joint="l_gripper_l_finger_joint" multiplier="-1.0"/>
      <dynamics damping="0.7" friction="0.0"/>
    </joint>
    <transmission name="gripper_left1">
      <type>transmission_interface/SimpleTransmission</type>
      <joint name="l_gripper_r_finger_joint">
        <hardwareInterface>EffortJointInterface</hardwareInterface>
      </joint>
      <actuator name="gripper_l1_motor1">
        <hardwareInterface>EffortJointInterface</hardwareInterface>
        <mechanicalReduction>1</mechanicalReduction>
      </actuator>
    </transmission>
    <transmission name="gripper_left2">
      <type>transmission_interface/SimpleTransmission</type>
      <joint name="l_gripper_l_finger_joint">
        <hardwareInterface>EffortJointInterface</hardwareInterface>
      </joint>
      <actuator name="gripper_l1_motor2">
        <hardwareInterface>EffortJointInterface</hardwareInterface>
        <mechanicalReduction>1</mechanicalReduction>
      </actuator>
    </transmission>
    <gazebo reference="l_gripper_r_finger_joint">
      <implicitSpringDamper>1</implicitSpringDamper>
    </gazebo>
    <gazebo reference="l_gripper_l_finger_joint">
      <implicitSpringDamper>1</implicitSpringDamper>
    </gazebo>
  
    <joint name="left_gripper_mass" type="fixed">
      <child link="left_gripper_mass">
      </child>
      <origin rpy="0.0 0.0 0.0" xyz="0.0 0.0 0.0240000000000000">
      </origin>
      <parent link="left_hand">
      </parent>
    </joint>
    <joint name="left_gripper_object_mass" type="fixed">
      <child link="left_gripper_object_mass">
      </child>
      <origin rpy="0.0 0.0 0.0" xyz="0.0 0.0 0.0450000000000000">
      </origin>
      <parent link="left_gripper_mass">
      </parent>
    </joint>
    <link name="left_gripper_mass">
      <inertial>
        <inertia ixx="1.00000000000000e-08" ixy="0.0" ixz="0.0" iyy="1.00000000000000e-08" iyz="0.0" izz="1.00000000000000e-08">
        </inertia>
        <mass value="0.000100000000000000">
        </mass>
        <origin rpy="0.0 0.0 0.0" xyz="0.0 0.0 0.0">
        </origin>
      </inertial>
    </link>
    <link name="left_gripper_object_mass">
      <inertial>
        <inertia ixx="1.00000000000000e-08" ixy="0.0" ixz="0.0" iyy="1.00000000000000e-08" iyz="0.0" izz="1.00000000000000e-08">
        </inertia>
        <mass value="0.000100000000000000">
        </mass>
        <origin rpy="0.0 0.0 0.0" xyz="0.0 0.0 0.0">
        </origin>
      </inertial>
    </link>
  
    <link name="finger_1_/flex_link_1_">
      <visual>
        <origin rpy="1.57075 0 1.57075" xyz="0 -0.007 0"/>
        <geometry>
          <mesh filename="package://reflex_visualizer/meshes/flex_block.STL"/>
        </geometry>
        <material name="">
          <color rgba="0.2 0.2 .2 1"/>
        </material>
      </visual>
    </link>
    <link name="finger_1_/flex_link_2_">
      <visual>
        <origin rpy="1.57075 0 1.57075" xyz="0 -0.007 0"/>
        <geometry>
          <mesh filename="package://reflex_visualizer/meshes/flex_block.STL"/>
        </geometry>
        <material name="">
          <color rgba="0.2 0.2 .2 1"/>
        </material>
      </visual>
    </link>
    <link name="finger_1_/flex_link_3_">
      <visual>
        <origin rpy="1.57075 0 1.57075" xyz="0 -0.007 0"/>
        <geometry>
          <mesh filename="package://reflex_visualizer/meshes/flex_block.STL"/>
        </geometry>
        <material name="">
          <color rgba="0.2 0.2 .2 1"/>
        </material>
      </visual>
    </link>
    <link name="finger_1_/flex_link_4_">
      <visual>
        <origin rpy="1.57075 0 1.57075" xyz="0 -0.007 0"/>
        <geometry>
          <mesh filename="package://reflex_visualizer/meshes/flex_block.STL"/>
        </geometry>
        <material name="">
          <color rgba="0.2 0.2 .2 1"/>
        </material>
      </visual>
    </link>
    <link name="finger_1_/flex_link_5_">
      <visual>
        <origin rpy="1.57075 0 1.57075" xyz="0 -0.007 0"/>
        <geometry>
          <mesh filename="package://reflex_visualizer/meshes/flex_block.STL"/>
        </geometry>
        <material name="">
          <color rgba="0.2 0.2 .2 1"/>
        </material>
      </visual>
    </link>
    <link name="finger_1_/flex_link_6_">
      <visual>
        <origin rpy="1.57075 0 1.57075" xyz="0 -0.007 0"/>
        <geometry>
          <mesh filename="package://reflex_visualizer/meshes/flex_block.STL"/>
        </geometry>
        <material name="">
          <color rgba="0.2 0.2 .2 1"/>
        </material>
      </visual>
    </link>
    <link name="finger_1_/flex_link_7_">
      <visual>
        <origin rpy="1.57075 0 1.57075" xyz="0 -0.007 0"/>
        <geometry>
          <mesh filename="package://reflex_visualizer/meshes/flex_block.STL"/>
        </geometry>
        <material name="">
          <color rgba="0.2 0.2 .2 1"/>
        </material>
      </visual>
    </link>
    <link name="finger_1_/flex_link_8_">
      <visual>
        <origin rpy="1.57075 0 1.57075" xyz="0 -0.007 0"/>
        <geometry>
          <mesh filename="package://reflex_visualizer/meshes/flex_block.STL"/>
        </geometry>
        <material name="">
          <color rgba="0.2 0.2 .2 1"/>
        </material>
      </visual>
    </link>
    <link name="finger_1_/flex_link_9_">
      <visual>
        <origin rpy="1.57075 0 1.57075" xyz="0 -0.007 0"/>
        <geometry>
          <mesh filename="package://reflex_visualizer/meshes/flex_block.STL"/>
        </geometry>
        <material name="">
          <color rgba="0.2 0.2 .2 1"/>
        </material>
      </visual>
    </link>
    <joint name="finger_1_/flex_joint_from_1_to_2" type="continuous">
      <parent link="finger_1_/flex_link_1_"/>
      <child link="finger_1_/flex_link_2_"/>
      <origin xyz="0.00177777777778 0 0"/>
      <axis xyz="0 -1 0"/>
    </joint>
    <joint name="finger_1_/flex_joint_from_2_to_3" type="continuous">
      <parent link="finger_1_/flex_link_2_"/>
      <child link="finger_1_/flex_link_3_"/>
      <origin xyz="0.00177777777778 0 0"/>
      <axis xyz="0 -1 0"/>
    </joint>
    <joint name="finger_1_/flex_joint_from_3_to_4" type="continuous">
      <parent link="finger_1_/flex_link_3_"/>
      <child link="finger_1_/flex_link_4_"/>
      <origin xyz="0.00177777777778 0 0"/>
      <axis xyz="0 -1 0"/>
    </joint>
    <joint name="finger_1_/flex_joint_from_4_to_5" type="continuous">
      <parent link="finger_1_/flex_link_4_"/>
      <child link="finger_1_/flex_link_5_"/>
      <origin xyz="0.00177777777778 0 0"/>
      <axis xyz="0 -1 0"/>
    </joint>
    <joint name="finger_1_/flex_joint_from_5_to_6" type="continuous">
      <parent link="finger_1_/flex_link_5_"/>
      <child link="finger_1_/flex_link_6_"/>
      <origin xyz="0.00177777777778 0 0"/>
      <axis xyz="0 -1 0"/>
    </joint>
    <joint name="finger_1_/flex_joint_from_6_to_7" type="continuous">
      <parent link="finger_1_/flex_link_6_"/>
      <child link="finger_1_/flex_link_7_"/>
      <origin xyz="0.00177777777778 0 0"/>
      <axis xyz="0 -1 0"/>
    </joint>
    <joint name="finger_1_/flex_joint_from_7_to_8" type="continuous">
      <parent link="finger_1_/flex_link_7_"/>
      <child link="finger_1_/flex_link_8_"/>
      <origin xyz="0.00177777777778 0 0"/>
      <axis xyz="0 -1 0"/>
    </joint>
    <joint name="finger_1_/flex_joint_from_8_to_9" type="continuous">
      <parent link="finger_1_/flex_link_8_"/>
      <child link="finger_1_/flex_link_9_"/>
      <origin xyz="0.00177777777778 0 0"/>
      <axis xyz="0 -1 0"/>
    </joint>
    <joint name="finger_1_/flex_joint_from_prox_to_1" type="continuous">
      <parent link="proximal_1"/>
      <child link="finger_1_/flex_link_1_"/>
      <origin xyz="0.06 0 -0.004"/>
      <axis xyz="0 -1 0"/>
    </joint>
    <joint name="finger_1_/flex_joint_from_9_to_dist" type="continuous">
      <parent link="finger_1_/flex_link_9_"/>
      <child link="distal_1"/>
      <origin xyz="-0.00822222222222 0 0.008"/>
      <axis xyz="0 -1 0"/>
    </joint>
    <link name="finger_2_/flex_link_1_">
      <visual>
        <origin rpy="1.57075 0 1.57075" xyz="0 -0.007 0"/>
        <geometry>
          <mesh filename="package://reflex_visualizer/meshes/flex_block.STL"/>
        </geometry>
        <material name="">
          <color rgba="0.2 0.2 .2 1"/>
        </material>
      </visual>
    </link>
    <link name="finger_2_/flex_link_2_">
      <visual>
        <origin rpy="1.57075 0 1.57075" xyz="0 -0.007 0"/>
        <geometry>
          <mesh filename="package://reflex_visualizer/meshes/flex_block.STL"/>
        </geometry>
        <material name="">
          <color rgba="0.2 0.2 .2 1"/>
        </material>
      </visual>
    </link>
    <link name="finger_2_/flex_link_3_">
      <visual>
        <origin rpy="1.57075 0 1.57075" xyz="0 -0.007 0"/>
        <geometry>
          <mesh filename="package://reflex_visualizer/meshes/flex_block.STL"/>
        </geometry>
        <material name="">
          <color rgba="0.2 0.2 .2 1"/>
        </material>
      </visual>
    </link>
    <link name="finger_2_/flex_link_4_">
      <visual>
        <origin rpy="1.57075 0 1.57075" xyz="0 -0.007 0"/>
        <geometry>
          <mesh filename="package://reflex_visualizer/meshes/flex_block.STL"/>
        </geometry>
        <material name="">
          <color rgba="0.2 0.2 .2 1"/>
        </material>
      </visual>
    </link>
    <link name="finger_2_/flex_link_5_">
      <visual>
        <origin rpy="1.57075 0 1.57075" xyz="0 -0.007 0"/>
        <geometry>
          <mesh filename="package://reflex_visualizer/meshes/flex_block.STL"/>
        </geometry>
        <material name="">
          <color rgba="0.2 0.2 .2 1"/>
        </material>
      </visual>
    </link>
    <link name="finger_2_/flex_link_6_">
      <visual>
        <origin rpy="1.57075 0 1.57075" xyz="0 -0.007 0"/>
        <geometry>
          <mesh filename="package://reflex_visualizer/meshes/flex_block.STL"/>
        </geometry>
        <material name="">
          <color rgba="0.2 0.2 .2 1"/>
        </material>
      </visual>
    </link>
    <link name="finger_2_/flex_link_7_">
      <visual>
        <origin rpy="1.57075 0 1.57075" xyz="0 -0.007 0"/>
        <geometry>
          <mesh filename="package://reflex_visualizer/meshes/flex_block.STL"/>
        </geometry>
        <material name="">
          <color rgba="0.2 0.2 .2 1"/>
        </material>
      </visual>
    </link>
    <link name="finger_2_/flex_link_8_">
      <visual>
        <origin rpy="1.57075 0 1.57075" xyz="0 -0.007 0"/>
        <geometry>
          <mesh filename="package://reflex_visualizer/meshes/flex_block.STL"/>
        </geometry>
        <material name="">
          <color rgba="0.2 0.2 .2 1"/>
        </material>
      </visual>
    </link>
    <link name="finger_2_/flex_link_9_">
      <visual>
        <origin rpy="1.57075 0 1.57075" xyz="0 -0.007 0"/>
        <geometry>
          <mesh filename="package://reflex_visualizer/meshes/flex_block.STL"/>
        </geometry>
        <material name="">
          <color rgba="0.2 0.2 .2 1"/>
        </material>
      </visual>
    </link>
    <joint name="finger_2_/flex_joint_from_1_to_2" type="continuous">
      <parent link="finger_2_/flex_link_1_"/>
      <child link="finger_2_/flex_link_2_"/>
      <origin xyz="0.00177777777778 0 0"/>
      <axis xyz="0 -1 0"/>
    </joint>
    <joint name="finger_2_/flex_joint_from_2_to_3" type="continuous">
      <parent link="finger_2_/flex_link_2_"/>
      <child link="finger_2_/flex_link_3_"/>
      <origin xyz="0.00177777777778 0 0"/>
      <axis xyz="0 -1 0"/>
    </joint>
    <joint name="finger_2_/flex_joint_from_3_to_4" type="continuous">
      <parent link="finger_2_/flex_link_3_"/>
      <child link="finger_2_/flex_link_4_"/>
      <origin xyz="0.00177777777778 0 0"/>
      <axis xyz="0 -1 0"/>
    </joint>
    <joint name="finger_2_/flex_joint_from_4_to_5" type="continuous">
      <parent link="finger_2_/flex_link_4_"/>
      <child link="finger_2_/flex_link_5_"/>
      <origin xyz="0.00177777777778 0 0"/>
      <axis xyz="0 -1 0"/>
    </joint>
    <joint name="finger_2_/flex_joint_from_5_to_6" type="continuous">
      <parent link="finger_2_/flex_link_5_"/>
      <child link="finger_2_/flex_link_6_"/>
      <origin xyz="0.00177777777778 0 0"/>
      <axis xyz="0 -1 0"/>
    </joint>
    <joint name="finger_2_/flex_joint_from_6_to_7" type="continuous">
      <parent link="finger_2_/flex_link_6_"/>
      <child link="finger_2_/flex_link_7_"/>
      <origin xyz="0.00177777777778 0 0"/>
      <axis xyz="0 -1 0"/>
    </joint>
    <joint name="finger_2_/flex_joint_from_7_to_8" type="continuous">
      <parent link="finger_2_/flex_link_7_"/>
      <child link="finger_2_/flex_link_8_"/>
      <origin xyz="0.00177777777778 0 0"/>
      <axis xyz="0 -1 0"/>
    </joint>
    <joint name="finger_2_/flex_joint_from_8_to_9" type="continuous">
      <parent link="finger_2_/flex_link_8_"/>
      <child link="finger_2_/flex_link_9_"/>
      <origin xyz="0.00177777777778 0 0"/>
      <axis xyz="0 -1 0"/>
    </joint>
    <joint name="finger_2_/flex_joint_from_prox_to_1" type="continuous">
      <parent link="proximal_2"/>
      <child link="finger_2_/flex_link_1_"/>
      <origin xyz="0.06 0 -0.004"/>
      <axis xyz="0 -1 0"/>
    </joint>
    <joint name="finger_2_/flex_joint_from_9_to_dist" type="continuous">
      <parent link="finger_2_/flex_link_9_"/>
      <child link="distal_2"/>
      <origin xyz="-0.00822222222222 0 0.008"/>
      <axis xyz="0 -1 0"/>
    </joint>
    <link name="finger_3_/flex_link_1_">
      <visual>
        <origin rpy="1.57075 0 1.57075" xyz="0 -0.007 0"/>
        <geometry>
          <mesh filename="package://reflex_visualizer/meshes/flex_block.STL"/>
        </geometry>
        <material name="">
          <color rgba="0.2 0.2 .2 1"/>
        </material>
      </visual>
    </link>
    <link name="finger_3_/flex_link_2_">
      <visual>
        <origin rpy="1.57075 0 1.57075" xyz="0 -0.007 0"/>
        <geometry>
          <mesh filename="package://reflex_visualizer/meshes/flex_block.STL"/>
        </geometry>
        <material name="">
          <color rgba="0.2 0.2 .2 1"/>
        </material>
      </visual>
    </link>
    <link name="finger_3_/flex_link_3_">
      <visual>
        <origin rpy="1.57075 0 1.57075" xyz="0 -0.007 0"/>
        <geometry>
          <mesh filename="package://reflex_visualizer/meshes/flex_block.STL"/>
        </geometry>
        <material name="">
          <color rgba="0.2 0.2 .2 1"/>
        </material>
      </visual>
    </link>
    <link name="finger_3_/flex_link_4_">
      <visual>
        <origin rpy="1.57075 0 1.57075" xyz="0 -0.007 0"/>
        <geometry>
          <mesh filename="package://reflex_visualizer/meshes/flex_block.STL"/>
        </geometry>
        <material name="">
          <color rgba="0.2 0.2 .2 1"/>
        </material>
      </visual>
    </link>
    <link name="finger_3_/flex_link_5_">
      <visual>
        <origin rpy="1.57075 0 1.57075" xyz="0 -0.007 0"/>
        <geometry>
          <mesh filename="package://reflex_visualizer/meshes/flex_block.STL"/>
        </geometry>
        <material name="">
          <color rgba="0.2 0.2 .2 1"/>
        </material>
      </visual>
    </link>
    <link name="finger_3_/flex_link_6_">
      <visual>
        <origin rpy="1.57075 0 1.57075" xyz="0 -0.007 0"/>
        <geometry>
          <mesh filename="package://reflex_visualizer/meshes/flex_block.STL"/>
        </geometry>
        <material name="">
          <color rgba="0.2 0.2 .2 1"/>
        </material>
      </visual>
    </link>
    <link name="finger_3_/flex_link_7_">
      <visual>
        <origin rpy="1.57075 0 1.57075" xyz="0 -0.007 0"/>
        <geometry>
          <mesh filename="package://reflex_visualizer/meshes/flex_block.STL"/>
        </geometry>
        <material name="">
          <color rgba="0.2 0.2 .2 1"/>
        </material>
      </visual>
    </link>
    <link name="finger_3_/flex_link_8_">
      <visual>
        <origin rpy="1.57075 0 1.57075" xyz="0 -0.007 0"/>
        <geometry>
          <mesh filename="package://reflex_visualizer/meshes/flex_block.STL"/>
        </geometry>
        <material name="">
          <color rgba="0.2 0.2 .2 1"/>
        </material>
      </visual>
    </link>
    <link name="finger_3_/flex_link_9_">
      <visual>
        <origin rpy="1.57075 0 1.57075" xyz="0 -0.007 0"/>
        <geometry>
          <mesh filename="package://reflex_visualizer/meshes/flex_block.STL"/>
        </geometry>
        <material name="">
          <color rgba="0.2 0.2 .2 1"/>
        </material>
      </visual>
    </link>
    <joint name="finger_3_/flex_joint_from_1_to_2" type="continuous">
      <parent link="finger_3_/flex_link_1_"/>
      <child link="finger_3_/flex_link_2_"/>
      <origin xyz="0.00177777777778 0 0"/>
      <axis xyz="0 -1 0"/>
    </joint>
    <joint name="finger_3_/flex_joint_from_2_to_3" type="continuous">
      <parent link="finger_3_/flex_link_2_"/>
      <child link="finger_3_/flex_link_3_"/>
      <origin xyz="0.00177777777778 0 0"/>
      <axis xyz="0 -1 0"/>
    </joint>
    <joint name="finger_3_/flex_joint_from_3_to_4" type="continuous">
      <parent link="finger_3_/flex_link_3_"/>
      <child link="finger_3_/flex_link_4_"/>
      <origin xyz="0.00177777777778 0 0"/>
      <axis xyz="0 -1 0"/>
    </joint>
    <joint name="finger_3_/flex_joint_from_4_to_5" type="continuous">
      <parent link="finger_3_/flex_link_4_"/>
      <child link="finger_3_/flex_link_5_"/>
      <origin xyz="0.00177777777778 0 0"/>
      <axis xyz="0 -1 0"/>
    </joint>
    <joint name="finger_3_/flex_joint_from_5_to_6" type="continuous">
      <parent link="finger_3_/flex_link_5_"/>
      <child link="finger_3_/flex_link_6_"/>
      <origin xyz="0.00177777777778 0 0"/>
      <axis xyz="0 -1 0"/>
    </joint>
    <joint name="finger_3_/flex_joint_from_6_to_7" type="continuous">
      <parent link="finger_3_/flex_link_6_"/>
      <child link="finger_3_/flex_link_7_"/>
      <origin xyz="0.00177777777778 0 0"/>
      <axis xyz="0 -1 0"/>
    </joint>
    <joint name="finger_3_/flex_joint_from_7_to_8" type="continuous">
      <parent link="finger_3_/flex_link_7_"/>
      <child link="finger_3_/flex_link_8_"/>
      <origin xyz="0.00177777777778 0 0"/>
      <axis xyz="0 -1 0"/>
    </joint>
    <joint name="finger_3_/flex_joint_from_8_to_9" type="continuous">
      <parent link="finger_3_/flex_link_8_"/>
      <child link="finger_3_/flex_link_9_"/>
      <origin xyz="0.00177777777778 0 0"/>
      <axis xyz="0 -1 0"/>
    </joint>
    <joint name="finger_3_/flex_joint_from_prox_to_1" type="continuous">
      <parent link="proximal_3"/>
      <child link="finger_3_/flex_link_1_"/>
      <origin xyz="0.06 0 -0.004"/>
      <axis xyz="0 -1 0"/>
    </joint>
    <joint name="finger_3_/flex_joint_from_9_to_dist" type="continuous">
      <parent link="finger_3_/flex_link_9_"/>
      <child link="distal_3"/>
      <origin xyz="-0.00822222222222 0 0.008"/>
      <axis xyz="0 -1 0"/>
    </joint>
    <joint name="right_gripper_base" type="fixed">
      <origin rpy="0 0 -1.57075" xyz="-0.03 0 0.015"/>
      <parent link="right_hand"/>
      <child link="right_gripper_base"/>
    </joint>
    <link name="right_gripper_base">
      <visual>
        <origin rpy="0 0 0" xyz="0 0 0"/>
        <geometry>
          <mesh filename="package://reflex_visualizer/meshes/base_link.STL"/>
        </geometry>
        <material name="">
          <color rgba="0.1 0.1 0.1 1"/>
        </material>
      </visual>
    </link>
    <link name="pad">
      <visual>
        <origin rpy="0 0 0" xyz="0 0 0"/>
        <geometry>
          <mesh filename="package://reflex_visualizer/meshes/pad.STL"/>
        </geometry>
        <material name="">
          <color rgba="0.106 0.227 0.631 1"/>
        </material>
      </visual>
      <collision>
        <origin rpy="0 0 0" xyz="0.0 0 0.015"/>
        <geometry>
          <cylinder length="0.12" radius="0.05"/>
        </geometry>
      </collision>
    </link>
    <joint name="pad_joint" type="fixed">
      <origin rpy="1.5707963267949 5.55111512312578E-17 -1.5707963267949" xyz="0.02 0 0.063"/>
      <parent link="right_gripper_base"/>
      <child link="pad"/>
      <axis xyz="0 0 0"/>
    </joint>
    <joint name="right_endpoint" type="fixed">
      <origin rpy="0 0 0" xyz="0 0 0"/>
      <parent link="right_gripper_base"/>
      <child link="right_gripper"/>
    </joint>
    <link name="right_gripper">
      <inertial>
        <origin rpy="0 0 0" xyz="0 0 0"/>
        <mass value="0.0000"/>
        <inertia ixx="0" ixy="0" ixz="0" iyy="0" iyz="0" izz="0.0"/>
      </inertial>
    </link>
    <link name="swivel_1">
      <visual>
        <origin rpy="0 0 0" xyz="0 0 0"/>
        <geometry>
          <mesh filename="package://reflex_visualizer/meshes/swivel_1.STL"/>
        </geometry>
        <material name="">
          <color rgba="0.1 0.1 0.1 1"/>
        </material>
      </visual>
    </link>
    <joint name="preshape_1" type="continuous">
      <origin rpy="6.75550818663469E-16 1.97993848419069E-16 -2.77555756156289E-16" xyz="0.0503973683071414 -0.026 0.063"/>
      <parent link="right_gripper_base"/>
      <child link="swivel_1"/>
      <axis xyz="0 0 -1"/>
    </joint>
    <link name="proximal_1">
      <visual>
        <origin rpy="0 0 0" xyz="0 0 0"/>
        <geometry>
          <mesh filename="package://reflex_visualizer/meshes/proximal_1.STL"/>
        </geometry>
        <material name="">
          <color rgba="0.16 0.16 0.16 1"/>
        </material>
      </visual>
    </link>
    <joint name="proximal_joint_1" type="continuous">
      <origin rpy="-6.20039667432211E-16 2.40507565059625E-17 2.22044604925031E-16" xyz="0.01 0 0.0186"/>
      <parent link="swivel_1"/>
      <child link="proximal_1"/>
      <axis xyz="0 -1 0"/>
    </joint>
    <link name="proximal_pad_1">
      <visual>
        <origin rpy="0 0 0" xyz="0 0 0"/>
        <geometry>
          <mesh filename="package://reflex_visualizer/meshes/proximal_pad_1.STL"/>
        </geometry>
        <material name="">
          <color rgba="0.106 0.227 0.631 1"/>
        </material>
      </visual>
    </link>
    <joint name="prox1_pad_joint" type="fixed">
      <origin rpy="1.5707963267949 0 -1.5707963267949" xyz="0 0 0"/>
      <parent link="proximal_1"/>
      <child link="proximal_pad_1"/>
      <axis xyz="0 0 0"/>
    </joint>
    <link name="distal_1">
      <visual>
        <origin rpy="0 0 0" xyz="0.01 0 -0.004"/>
        <geometry>
          <mesh filename="package://reflex_visualizer/meshes/distal_1.STL"/>
        </geometry>
        <material name="">
          <color rgba="0.16 0.16 0.16 1"/>
        </material>
      </visual>
    </link>
    <joint name="distal_joint_1" type="continuous">
      <origin rpy="0 0 0" xyz="0.0760000000000001 0 0.00250000000000002"/>
      <parent link="proximal_1"/>
      <child link="distal_1"/>
      <axis xyz="0 -1 0"/>
    </joint>
    <link name="distal_pad_1">
      <visual>
        <origin rpy="0 0 0" xyz="0 -0.004 -0.01"/>
        <geometry>
          <mesh filename="package://reflex_visualizer/meshes/distal_pad_1.STL"/>
        </geometry>
        <material name="">
          <color rgba="0.106 0.227 0.631 1"/>
        </material>
      </visual>
    </link>
    <joint name="dist1_pad_joint" type="fixed">
      <origin rpy="1.5707963267949 0 -1.5707963267949" xyz="-0.0760000000000001 0 -0.0025"/>
      <parent link="distal_1"/>
      <child link="distal_pad_1"/>
      <axis xyz="0 0 0"/>
    </joint>
    <link name="swivel_2">
      <visual>
        <origin rpy="0 0 0" xyz="0 0 0"/>
        <geometry>
          <mesh filename="package://reflex_visualizer/meshes/swivel_2.STL"/>
        </geometry>
        <material name="">
          <color rgba="0.1 0.1 0.1 1"/>
        </material>
      </visual>
    </link>
    <joint name="preshape_2" type="continuous">
      <origin rpy="1.22459340959228E-15 -7.33448407631817E-16 -1.66533453693773E-16" xyz="0.0503973683071413 0.0259999999999999 0.063"/>
      <parent link="right_gripper_base"/>
      <child link="swivel_2"/>
      <axis xyz="0 0 -1"/>
    </joint>
    <link name="proximal_2">
      <visual>
        <origin rpy="0 0 0" xyz="0 0 0"/>
        <geometry>
          <mesh filename="package://reflex_visualizer/meshes/proximal_2.STL"/>
        </geometry>
        <material name="">
          <color rgba="0.16 0.16 0.16 1"/>
        </material>
      </visual>
    </link>
    <joint name="proximal_joint_2" type="continuous">
      <origin rpy="-1.16908225836102E-15 9.55493012556849E-16 1.11022302462515E-16" xyz="0.01 0 0.0186"/>
      <parent link="swivel_2"/>
      <child link="proximal_2"/>
      <axis xyz="0 -1 0"/>
    </joint>
    <link name="proximal_pad_2">
      <visual>
        <origin rpy="0 0 0" xyz="0 0 0"/>
        <geometry>
          <mesh filename="package://reflex_visualizer/meshes/proximal_pad_2.STL"/>
        </geometry>
        <material name="">
          <color rgba="0.106 0.227 0.631 1"/>
        </material>
      </visual>
    </link>
    <joint name="prox2_pad_joint" type="fixed">
      <origin rpy="1.5707963267949 0 -1.5707963267949" xyz="0 0 0"/>
      <parent link="proximal_2"/>
      <child link="proximal_pad_2"/>
      <axis xyz="0 0 0"/>
    </joint>
    <link name="distal_2">
      <visual>
        <origin rpy="0 0 0" xyz="0.01 0 -0.004"/>
        <geometry>
          <mesh filename="package://reflex_visualizer/meshes/distal_2.STL"/>
        </geometry>
        <material name="">
          <color rgba="0.16 0.16 0.16 1"/>
        </material>
      </visual>
    </link>
    <joint name="distal_joint_2" type="continuous">
      <origin rpy="0 0 0" xyz="0.0760000000000001 0 0.00249999999999997"/>
      <parent link="proximal_2"/>
      <child link="distal_2"/>
      <axis xyz="0 -1 0"/>
    </joint>
    <link name="distal_pad_2">
      <visual>
        <origin rpy="0 0 0" xyz="0 -0.004 -0.01"/>
        <geometry>
          <mesh filename="package://reflex_visualizer/meshes/distal_pad_2.STL"/>
        </geometry>
        <material name="">
          <color rgba="0.106 0.227 0.631 1"/>
        </material>
      </visual>
    </link>
    <joint name="dist2_pad_joint" type="fixed">
      <origin rpy="1.5707963267949 0 -1.5707963267949" xyz="-0.0760000000000001 0 -0.0025"/>
      <parent link="distal_2"/>
      <child link="distal_pad_2"/>
      <axis xyz="0 0 0"/>
    </joint>
    <link name="proximal_3">
      <visual>
        <origin rpy="0 0 0" xyz="0 0 0"/>
        <geometry>
          <mesh filename="package://reflex_visualizer/meshes/proximal_3.STL"/>
        </geometry>
        <material name="">
          <color rgba="0.16 0.16 0.16 1"/>
        </material>
      </visual>
    </link>
    <joint name="proximal_joint_3" type="continuous">
      <origin rpy="-5.55111512312578E-17 -2.22044604925031E-16 3.14159265358979" xyz="-0.0299999999999996 0 0.0816000000000002"/>
      <parent link="right_gripper_base"/>
      <child link="proximal_3"/>
      <axis xyz="0 -1 0"/>
    </joint>
    <link name="proximal_pad_3">
      <visual>
        <origin rpy="0 0 0" xyz="0 0 0"/>
        <geometry>
          <mesh filename="package://reflex_visualizer/meshes/proximal_pad_3.STL"/>
        </geometry>
        <material name="">
          <color rgba="0.106 0.227 0.631 1"/>
        </material>
      </visual>
    </link>
    <joint name="prox3_pad_joint" type="fixed">
      <origin rpy="1.5707963267949 1.22460635382238E-16 -1.5707963267949" xyz="0 0 0"/>
      <parent link="proximal_3"/>
      <child link="proximal_pad_3"/>
      <axis xyz="0 0 0"/>
    </joint>
    <link name="distal_3">
      <visual>
        <origin rpy="0 0 0" xyz="0.01 0 -0.004"/>
        <geometry>
          <mesh filename="package://reflex_visualizer/meshes/distal_3.STL"/>
        </geometry>
        <material name="">
          <color rgba="0.16 0.16 0.16 1"/>
        </material>
      </visual>
    </link>
    <joint name="distal_joint_3" type="continuous">
      <origin rpy="-1.48887961834512E-45 -1.0995850059156E-76 -7.38531841236285E-32" xyz="0.0760000000000001 0 0.0025"/>
      <parent link="proximal_3"/>
      <child link="distal_3"/>
      <axis xyz="0 -1 0"/>
    </joint>
    <link name="distal_pad_3">
      <visual>
        <origin rpy="0 0 0" xyz="0 -0.004 -0.01"/>
        <geometry>
          <mesh filename="package://reflex_visualizer/meshes/distal_pad_3.STL"/>
        </geometry>
        <material name="">
          <color rgba="0.106 0.227 0.631 1"/>
        </material>
      </visual>
    </link>
    <joint name="dist3_pad_joint" type="fixed">
      <origin rpy="1.5707963267949 -1.22460635382238E-16 -1.5707963267949" xyz="-0.0760000000000001 0 -0.0025"/>
      <parent link="distal_3"/>
      <child link="distal_pad_3"/>
      <axis xyz="0 0 0"/>
    </joint>
    <joint name="base_tactile_joint" type="fixed">
      <origin rpy="0 0 0" xyz="0 0 0"/>
      <parent link="right_gripper_base"/>
      <child link="base_tactile"/>
    </joint>
    <link name="base_tactile"/>
    <link name="proximal_1_tactile"/>
    <joint name="proximal_1_tactile_joint" type="fixed">
      <origin rpy="0 0 0" xyz="0 0 0"/>
      <parent link="proximal_1"/>
      <child link="proximal_1_tactile"/>
    </joint>
    <joint name="proximal_2_tactile_joint" type="fixed">
      <origin rpy="0 0 0" xyz="0 0 0"/>
      <parent link="proximal_2"/>
      <child link="proximal_2_tactile"/>
    </joint>
    <link name="proximal_2_tactile"/>
    <joint name="proximal_3_tactile_joint" type="fixed">
      <origin rpy="0 0 0" xyz="0 0 0"/>
      <parent link="proximal_3"/>
      <child link="proximal_3_tactile"/>
    </joint>
    <link name="proximal_3_tactile"/>
    <joint name="distal_1_tactile_joint" type="fixed">
      <origin rpy="0 0 0" xyz="0 0 0"/>
      <parent link="distal_1"/>
      <child link="distal_1_tactile"/>
    </joint>
    <link name="distal_1_tactile"/>
    <joint name="distal_2_tactile_joint" type="fixed">
      <origin rpy="0 0 0" xyz="0 0 0"/>
      <parent link="distal_2"/>
      <child link="distal_2_tactile"/>
    </joint>
    <link name="distal_2_tactile"/>
    <joint name="distal_3_tactile_joint" type="fixed">
      <origin rpy="0 0 0" xyz="0 0 0"/>
      <parent link="distal_3"/>
      <child link="distal_3_tactile"/>
    </joint>
    <link name="distal_3_tactile"/>
  
    <joint name="right_gripper_mass" type="fixed">
      <child link="right_gripper_mass">
      </child>
      <origin rpy="0.0 0.0 0.0" xyz="0.0 0.0 0.0">
      </origin>
      <parent link="right_hand">
      </parent>
    </joint>
    <joint name="right_gripper_object_mass" type="fixed">
      <child link="right_gripper_object_mass">
      </child>
      <origin rpy="0.0 0.0 0.0" xyz="0.0 0.0 0.0">
      </origin>
      <parent link="right_gripper_mass">
      </parent>
    </joint>
    <link name="right_gripper_mass">
      <inertial>
        <inertia ixx="1.00000000000000e-08" ixy="0.0" ixz="0.0" iyy="1.00000000000000e-08" iyz="0.0" izz="1.00000000000000e-08">
        </inertia>
        <mass value="0.900000000000000">
        </mass>
        <origin rpy="0.0 0.0 0.0" xyz="0.00140000000000000 0.0 0.0740000000000000">
        </origin>
      </inertial>
    </link>
    <link name="right_gripper_object_mass">
      <inertial>
        <inertia ixx="1.00000000000000e-08" ixy="0.0" ixz="0.0" iyy="1.00000000000000e-08" iyz="0.0" izz="1.00000000000000e-08">
        </inertia>
        <mass value="0.000100000000000000">
        </mass>
        <origin rpy="0.0 0.0 0.0" xyz="0.0 0.0 0.0">
        </origin>
      </inertial>
    </link>
  
      <link name="pedestal">
  	    <visual>
  	      <origin xyz="0 0 0" rpy="0 0 0" />
  	      <geometry>
  	        <mesh filename="package://baxter_description/meshes/base/PEDESTAL.DAE" />
  	      </geometry>
  	      <material name="darkgray">
  	        <color rgba=".2 .2 .2 1" />
  	      </material>
  	    </visual>
              <collision>
                <origin rpy="0 0 0" xyz="-0.04 0 -0.775"/>
                <geometry>
                  <box size="0.92 0.83 0.3"/>
                </geometry>
              </collision>
  	    <inertial>
  	      <origin xyz="0 0 0" rpy="0 0 0" />
  	      <mass value="60.86397744" />
  	      <inertia ixx="5.0635929" ixy="0.00103417" ixz="0.80199628" iyy="6.08689388" iyz="0.00105311" izz="4.96191932" />
  	    </inertial>
      </link>
      <joint name="pedestal_fixed" type="fixed">
        <origin rpy="0 0 0" xyz="0.0 0.0 0.0"/>
        <parent link="torso"/>
        <child link="pedestal"/>
      </joint>
  </robot>
